I'm sorry, but an uncaught exception occurred.

While running game code:
  File "game/turn.rpy", line 387, in script
    python:
  File "game/turn.rpy", line 393, in <module>
    restore_playthrough(persistent.playthrough)
NameError: name 'restore_playthrough' is not defined

-- Full Traceback ------------------------------------------------------------

Full traceback:
  File "game/turn.rpy", line 387, in script
    python:
  File "D:\renpy-7.4.4-sdk\renpy\ast.py", line 1131, in execute
    renpy.python.py_exec_bytecode(self.code.bytecode, self.hide, store=self.store)
  File "D:\renpy-7.4.4-sdk\renpy\python.py", line 1061, in py_exec_bytecode
    exec(bytecode, globals, locals)
  File "game/turn.rpy", line 393, in <module>
    restore_playthrough(persistent.playthrough)
NameError: name 'restore_playthrough' is not defined

Windows-10-10.0.22621 AMD64
Ren'Py 8.0.3.22090809
untitled 0.1
Mon Mar 13 21:19:15 2023
